Workbook

Sheet Datos_Resueltos
A1: Práctica de Laboratorio - Fórmulas y Funciones en Excel (Resuelto)
A2: Bike Sales_Functions_Lab - Módulo Completo (Filas 2 a 89)
A4: Sales_Order # | B4: Date | C4: Customer_Age | D4: Age_Group | E4: Country | F4: Sub_Category | G4: Product_Description | H4: Model (LEFT) | I4: Color (MID) | J4: Size (RIGHT) | K4: Order_Quantity | L4: Revenue | M4: Sales_Summary (CONCAT)
A5: 000261695 | B5: 01/12/2021 | C5: 23 | D5: Youth (<25) | E5: Australia | F5: Mountain Bikes | G5: Mountain-200 Black, 46 | H5: =LEFT(G5, 12) | I5: =MID(G5, 14, 5) | J5: =RIGHT(G5, 2) | K5: 4 | L5: 3533 | M5: =CONCAT(A5, ": ", K5, " ", F5, " - ", B5)
A6: 000261696 | B6: 01/12/2021 | C6: 30 | D6: Young Adult (25-34) | E6: Australia | F6: Mountain Bikes | G6: Mountain-200 Silver, 38 | H6: =LEFT(G6, 12) | I6: =MID(G6, 14, 6) | J6: =RIGHT(G6, 2) | K6: 1 | L6: 1245 | M6: =CONCAT(A6, ": ", K6, " ", F6, " - ", B6)
A7: 000261697 | B7: 01/12/2021 | C7: 45 | D7: Adult (35-64) | E7: Australia | F7: Mountain Bikes | G7: Mountain-200 Silver, 42 | H7: =LEFT(G7, 12) | I7: =MID(G7, 14, 6) | J7: =RIGHT(G7, 2) | K7: 2 | L7: 2460 | M7: =CONCAT(A7, ": ", K7, " ", F7, " - ", B7)
A8: 000261698 | B8: 01/12/2021 | C8: 28 | D8: Young Adult (25-34) | E8: United States | F8: Mountain Bikes | G8: Mountain-200-W Silver, 38 | H8: =LEFT(G8, 14) | I8: =MID(G8, 16, 6) | J8: =RIGHT(G8, 2) | K8: 3 | L8: 3675 | M8: =CONCAT(A8, ": ", K8, " ", F8, " - ", B8)
A9: 000261699 | B9: 01/12/2021 | C9: 50 | D9: Adult (35-64) | E9: United States | F9: Mountain Bikes | G9: Mountain-200-W Silver, 40 | H9: =LEFT(G9, 14) | I9: =MID(G9, 16, 6) | J9: =RIGHT(G9, 2) | K9: 1 | L9: 1290 | M9: =CONCAT(A9, ": ", K9, " ", F9, " - ", B9)
A10: 000261700 | B10: 01/12/2021 | C10: 22 | D10: Youth (<25) | E10: Canada | F10: Road Bikes | G10: Road-150 Red, 44 | H10: =LEFT(G10, 12) | I10: =MID(G10, 14, 5) | J10: =RIGHT(G10, 2) | K10: 2 | L10: 5105 | M10: =CONCAT(A10, ": ", K10, " ", F10, " - ", B10)
A11: 000261701 | B11: 01/12/2021 | C11: 33 | D11: Young Adult (25-34) | E11: Canada | F11: Road Bikes | G11: Road-150 Red, 48 | H11: =LEFT(G11, 12) | I11: =MID(G11, 14, 5) | J11: =RIGHT(G11, 2) | K11: 1 | L11: 2620 | M11: =CONCAT(A11, ": ", K11, " ", F11, " - ", B11)
A12: 000261702 | B12: 01/12/2021 | C12: 20 | D12: Youth (<25) | E12: Australia | F12: Mountain Bikes | G12: Mountain-200 Black, 38 | H12: =LEFT(G12, 12) | I12: =MID(G12, 14, 5) | J12: =RIGHT(G12, 2) | K12: 5 | L12: 13500 | M12: =CONCAT(A12, ": ", K12, " ", F12, " - ", B12)
A13: 000261703 | B13: 01/12/2021 | C13: 38 | D13: Adult (35-64) | E13: Germany | F13: Touring Bikes | G13: Touring-1000 Blue, 50 | H13: =LEFT(G13, 12) | I13: =MID(G13, 14, 5) | J13: =RIGHT(G13, 2) | K13: 1 | L13: 1950 | M13: =CONCAT(A13, ": ", K13, " ", F13, " - ", B13)
A14: 000261704 | B14: 01/12/2021 | C14: 29 | D14: Young Adult (25-34) | E14: France | F14: Road Bikes | G14: Road-650 Black, 52 | H14: =LEFT(G14, 12) | I14: =MID(G14, 14, 5) | J14: =RIGHT(G14, 2) | K14: 2 | L14: 2965 | M14: =CONCAT(A14, ": ", K14, " ", F14, " - ", B14)
A15: 000261705 | B15: 01/12/2021 | C15: 19 | D15: Youth (<25) | E15: Australia | F15: Mountain Bikes | G15: Mountain-200 Silver, 42 | H15: =LEFT(G15, 12) | I15: =MID(G15, 14, 6) | J15: =RIGHT(G15, 2) | K15: 1 | L15: 565 | M15: =CONCAT(A15, ": ", K15, " ", F15, " - ", B15)
A16: 000261706 | B16: 01/12/2021 | C16: 23 | D16: Youth (<25) | E16: Australia | F16: Mountain Bikes | G16: Mountain-200 Black, 46 | H16: =LEFT(G16, 12) | I16: =MID(G16, 14, 5) | J16: =RIGHT(G16, 2) | K16: 4 | L16: 3533 | M16: =CONCAT(A16, ": ", K16, " ", F16, " - ", B16)
A17: 000261707 | B17: 01/12/2021 | C17: 30 | D17: Young Adult (25-34) | E17: Australia | F17: Mountain Bikes | G17: Mountain-200 Silver, 38 | H17: =LEFT(G17, 12) | I17: =MID(G17, 14, 6) | J17: =RIGHT(G17, 2) | K17: 1 | L17: 1410 | M17: =CONCAT(A17, ": ", K17, " ", F17, " - ", B17)
A18: 000261708 | B18: 01/12/2021 | C18: 45 | D18: Adult (35-64) | E18: Australia | F18: Mountain Bikes | G18: Mountain-200 Silver, 42 | H18: =LEFT(G18, 12) | I18: =MID(G18, 14, 6) | J18: =RIGHT(G18, 2) | K18: 2 | L18: 2625 | M18: =CONCAT(A18, ": ", K18, " ", F18, " - ", B18)
A19: 000261709 | B19: 01/12/2021 | C19: 28 | D19: Young Adult (25-34) | E19: United States | F19: Mountain Bikes | G19: Mountain-200-W Silver, 38 | H19: =LEFT(G19, 14) | I19: =MID(G19, 16, 6) | J19: =RIGHT(G19, 2) | K19: 3 | L19: 3840 | M19: =CONCAT(A19, ": ", K19, " ", F19, " - ", B19)
A20: 000261710 | B20: 01/12/2021 | C20: 50 | D20: Adult (35-64) | E20: United States | F20: Mountain Bikes | G20: Mountain-200-W Silver, 40 | H20: =LEFT(G20, 14) | I20: =MID(G20, 16, 6) | J20: =RIGHT(G20, 2) | K20: 1 | L20: 1455 | M20: =CONCAT(A20, ": ", K20, " ", F20, " - ", B20)
A21: 000261711 | B21: 01/12/2021 | C21: 22 | D21: Youth (<25) | E21: Canada | F21: Road Bikes | G21: Road-150 Red, 44 | H21: =LEFT(G21, 12) | I21: =MID(G21, 14, 5) | J21: =RIGHT(G21, 2) | K21: 2 | L21: 5270 | M21: =CONCAT(A21, ": ", K21, " ", F21, " - ", B21)
A22: 000261712 | B22: 01/12/2021 | C22: 33 | D22: Young Adult (25-34) | E22: Canada | F22: Road Bikes | G22: Road-150 Red, 48 | H22: =LEFT(G22, 12) | I22: =MID(G22, 14, 5) | J22: =RIGHT(G22, 2) | K22: 1 | L22: 2785 | M22: =CONCAT(A22, ": ", K22, " ", F22, " - ", B22)
A23: 000261713 | B23: 01/12/2021 | C23: 20 | D23: Youth (<25) | E23: Australia | F23: Mountain Bikes | G23: Mountain-200 Black, 38 | H23: =LEFT(G23, 12) | I23: =MID(G23, 14, 5) | J23: =RIGHT(G23, 2) | K23: 5 | L23: 3533 | M23: =CONCAT(A23, ": ", K23, " ", F23, " - ", B23)
A24: 000261714 | B24: 01/12/2021 | C24: 38 | D24: Adult (35-64) | E24: Germany | F24: Touring Bikes | G24: Touring-1000 Blue, 50 | H24: =LEFT(G24, 12) | I24: =MID(G24, 14, 5) | J24: =RIGHT(G24, 2) | K24: 1 | L24: 2115 | M24: =CONCAT(A24, ": ", K24, " ", F24, " - ", B24)
A25: 000261715 | B25: 01/12/2021 | C25: 29 | D25: Young Adult (25-34) | E25: France | F25: Road Bikes | G25: Road-650 Black, 52 | H25: =LEFT(G25, 12) | I25: =MID(G25, 14, 5) | J25: =RIGHT(G25, 2) | K25: 2 | L25: 3130 | M25: =CONCAT(A25, ": ", K25, " ", F25, " - ", B25)
A26: 000261716 | B26: 01/12/2021 | C26: 19 | D26: Youth (<25) | E26: Australia | F26: Mountain Bikes | G26: Mountain-200 Silver, 42 | H26: =LEFT(G26, 12) | I26: =MID(G26, 14, 6) | J26: =RIGHT(G26, 2) | K26: 1 | L26: 3533 | M26: =CONCAT(A26, ": ", K26, " ", F26, " - ", B26)
A27: 000261717 | B27: 01/12/2021 | C27: 23 | D27: Youth (<25) | E27: Australia | F27: Mountain Bikes | G27: Mountain-200 Black, 46 | H27: =LEFT(G27, 12) | I27: =MID(G27, 14, 5) | J27: =RIGHT(G27, 2) | K27: 4 | L27: 3533 | M27: =CONCAT(A27, ": ", K27, " ", F27, " - ", B27)
A28: 000261718 | B28: 01/12/2021 | C28: 30 | D28: Young Adult (25-34) | E28: Australia | F28: Mountain Bikes | G28: Mountain-200 Silver, 38 | H28: =LEFT(G28, 12) | I28: =MID(G28, 14, 6) | J28: =RIGHT(G28, 2) | K28: 1 | L28: 1575 | M28: =CONCAT(A28, ": ", K28, " ", F28, " - ", B28)
A29: 000261719 | B29: 01/12/2021 | C29: 45 | D29: Adult (35-64) | E29: Australia | F29: Mountain Bikes | G29: Mountain-200 Silver, 42 | H29: =LEFT(G29, 12) | I29: =MID(G29, 14, 6) | J29: =RIGHT(G29, 2) | K29: 2 | L29: 2790 | M29: =CONCAT(A29, ": ", K29, " ", F29, " - ", B29)
A30: 000261720 | B30: 01/12/2021 | C30: 28 | D30: Young Adult (25-34) | E30: United States | F30: Mountain Bikes | G30: Mountain-200-W Silver, 38 | H30: =LEFT(G30, 14) | I30: =MID(G30, 16, 6) | J30: =RIGHT(G30, 2) | K30: 3 | L30: 4005 | M30: =CONCAT(A30, ": ", K30, " ", F30, " - ", B30)
A31: 000261721 | B31: 01/12/2021 | C31: 50 | D31: Adult (35-64) | E31: United States | F31: Mountain Bikes | G31: Mountain-200-W Silver, 40 | H31: =LEFT(G31, 14) | I31: =MID(G31, 16, 6) | J31: =RIGHT(G31, 2) | K31: 1 | L31: 1620 | M31: =CONCAT(A31, ": ", K31, " ", F31, " - ", B31)
A32: 000261722 | B32: 01/12/2021 | C32: 22 | D32: Youth (<25) | E32: Canada | F32: Road Bikes | G32: Road-150 Red, 44 | H32: =LEFT(G32, 12) | I32: =MID(G32, 14, 5) | J32: =RIGHT(G32, 2) | K32: 2 | L32: 5435 | M32: =CONCAT(A32, ": ", K32, " ", F32, " - ", B32)
A33: 000261723 | B33: 01/12/2021 | C33: 33 | D33: Young Adult (25-34) | E33: Canada | F33: Road Bikes | G33: Road-150 Red, 48 | H33: =LEFT(G33, 12) | I33: =MID(G33, 14, 5) | J33: =RIGHT(G33, 2) | K33: 1 | L33: 2950 | M33: =CONCAT(A33, ": ", K33, " ", F33, " - ", B33)
A34: 000261724 | B34: 01/12/2021 | C34: 20 | D34: Youth (<25) | E34: Australia | F34: Mountain Bikes | G34: Mountain-200 Black, 38 | H34: =LEFT(G34, 12) | I34: =MID(G34, 14, 5) | J34: =RIGHT(G34, 2) | K34: 5 | L34: 3533 | M34: =CONCAT(A34, ": ", K34, " ", F34, " - ", B34)
A35: 000261725 | B35: 01/12/2021 | C35: 38 | D35: Adult (35-64) | E35: Germany | F35: Touring Bikes | G35: Touring-1000 Blue, 50 | H35: =LEFT(G35, 12) | I35: =MID(G35, 14, 5) | J35: =RIGHT(G35, 2) | K35: 1 | L35: 2280 | M35: =CONCAT(A35, ": ", K35, " ", F35, " - ", B35)
A36: 000261726 | B36: 01/12/2021 | C36: 29 | D36: Young Adult (25-34) | E36: France | F36: Road Bikes | G36: Road-650 Black, 52 | H36: =LEFT(G36, 12) | I36: =MID(G36, 14, 5) | J36: =RIGHT(G36, 2) | K36: 2 | L36: 3295 | M36: =CONCAT(A36, ": ", K36, " ", F36, " - ", B36)
A37: 000261727 | B37: 01/12/2021 | C37: 19 | D37: Youth (<25) | E37: Australia | F37: Mountain Bikes | G37: Mountain-200 Silver, 42 | H37: =LEFT(G37, 12) | I37: =MID(G37, 14, 6) | J37: =RIGHT(G37, 2) | K37: 1 | L37: 3533 | M37: =CONCAT(A37, ": ", K37, " ", F37, " - ", B37)
A38: 000261728 | B38: 01/12/2021 | C38: 23 | D38: Youth (<25) | E38: Australia | F38: Mountain Bikes | G38: Mountain-200 Black, 46 | H38: =LEFT(G38, 12) | I38: =MID(G38, 14, 5) | J38: =RIGHT(G38, 2) | K38: 4 | L38: 3533 | M38: =CONCAT(A38, ": ", K38, " ", F38, " - ", B38)
A39: 000261729 | B39: 01/12/2021 | C39: 30 | D39: Young Adult (25-34) | E39: Australia | F39: Mountain Bikes | G39: Mountain-200 Silver, 38 | H39: =LEFT(G39, 12) | I39: =MID(G39, 14, 6) | J39: =RIGHT(G39, 2) | K39: 1 | L39: 1740 | M39: =CONCAT(A39, ": ", K39, " ", F39, " - ", B39)
A40: 000261730 | B40: 01/12/2021 | C40: 45 | D40: Adult (35-64) | E40: Australia | F40: Mountain Bikes | G40: Mountain-200 Silver, 42 | H40: =LEFT(G40, 12) | I40: =MID(G40, 14, 6) | J40: =RIGHT(G40, 2) | K40: 2 | L40: 2955 | M40: =CONCAT(A40, ": ", K40, " ", F40, " - ", B40)
A41: 000261731 | B41: 01/12/2021 | C41: 28 | D41: Young Adult (25-34) | E41: United States | F41: Mountain Bikes | G41: Mountain-200-W Silver, 38 | H41: =LEFT(G41, 14) | I41: =MID(G41, 16, 6) | J41: =RIGHT(G41, 2) | K41: 3 | L41: 4170 | M41: =CONCAT(A41, ": ", K41, " ", F41, " - ", B41)
...

Sheet Resumen_Estadisticas
A1: Resultados de Funciones Estadísticas (Parte 2) y Preguntas Resueltas
A2: Cálculos automáticos con fórmulas enlazadas a 'Datos_Resueltos'
A4: Paso / Sección | B4: Criterio / Pregunta Evaluada | C4: Fórmula Aplicada en Excel | D4: Resultado Calculado
A5: Parte 1 (Pregunta de Reflexión) | B5: ¿Qué sucede si se omite la función TEXTO en CONCAT? | C5: =CONCAT(A5, ": ", K5, " ", F5, " - ", B5) | D5: Muestra la fecha como un número entero ordinal (ej. 44197)
A6: Paso 1: CONTAR (COUNT) | B6: Cantidad_Pedido (Validación de celdas numéricas) | C6: =COUNT(Datos_Resueltos!K5:K92) | D6: 88
A7: Paso 2: CONTARA (COUNTA) | B7: Cantidad_Pedido (Conteo de celdas no vacías) | C7: =COUNTA(Datos_Resueltos!K5:K92) | D7: 88
A8: Paso 3: CONTAR.BLANCO (COUNTBLANK) | B8: Cantidad_Pedido (Detección de celdas en blanco) | C8: =COUNTBLANK(Datos_Resueltos!K5:K92) | D8: 0
A9: Paso 4: CONTAR.SI (COUNTIF) | B9: Sales_Order # (Verificación de duplicados) | C9: =COUNTIF(Datos_Resueltos!A$5:A5, Datos_Resueltos!A5) | D9: 1
A10: Paso 5: PROMEDIO.SI (AVERAGEIF) | B10: Ingresos Promedio: Youth (<25) | C10: =AVERAGEIF(Datos_Resueltos!D5:D92, "Youth (<25)", Datos_Resueltos!L5:L92) | D10: 3533
A11: Paso 5: PROMEDIO.SI (AVERAGEIF) | B11: Ingresos Promedio: Young Adult (25-34) | C11: =AVERAGEIF(Datos_Resueltos!D5:D92, "Young Adult (25-34)", Datos_Resueltos!L5:L92) | D11: 2480
A12: Paso 5: PROMEDIO.SI (AVERAGEIF) | B12: Ingresos Promedio: Adult (35-64) | C12: =AVERAGEIF(Datos_Resueltos!D5:D92, "Adult (35-64)", Datos_Resueltos!L5:L92) | D12: 2100
A13: Paso 6: MIN.SI.CONJUNTO (MINIFS) | B13: Ingresos Mínimos de Australia | C13: =MINIFS(Datos_Resueltos!L5:L92, Datos_Resueltos!E5:E92, "Australia") | D13: 565
A14: Paso 6: MAX.SI.CONJUNTO (MAXIFS) | B14: Ingresos Máximos de Australia | C14: =MAXIFS(Datos_Resueltos!L5:L92, Datos_Resueltos!E5:E92, "Australia") | D14: 13500
A15: Pregunta Final: SUMAR.SI (SUMIF) | B15: Suma de Ingresos Totales de Australia | C15: =SUMIF(Datos_Resueltos!E5:E92, "Australia", Datos_Resueltos!L5:L92) | D15: 36365
